INFO:django.utils.autoreload:/mnt/d/cmu/capstone_1/base/urls.py changed, reloading.
ERROR:django.request:Internal Server Error: /admin-dashboard/
Traceback (most recent call last):
  File "/home/linzhan/anaconda3/lib/python3.12/site-packages/django/template/base.py", line 510, in parse
    compile_func = self.tags[command]
                   ~~~~~~~~~^^^^^^^^^
KeyError: 'endblock'

During handling of the above exception, another exception occurred:

Traceback (most recent call last):
  File "/home/linzhan/anaconda3/lib/python3.12/site-packages/django/core/handlers/exception.py", line 55, in inner
    response = get_response(request)
               ^^^^^^^^^^^^^^^^^^^^^
  File "/home/linzhan/anaconda3/lib/python3.12/site-packages/django/core/handlers/base.py", line 197, in _get_response
    response = wrapped_callback(request, *callback_args, **callback_kwargs)
               ^^^^^^^^^^^^^^^^^^^^^^^^^^^^^^^^^^^^^^^^^^^^^^^^^^^^^^^^^^^^
  File "/home/linzhan/anaconda3/lib/python3.12/site-packages/django/contrib/auth/decorators.py", line 60, in _view_wrapper
    return view_func(request, *args, **kwargs)
           ^^^^^^^^^^^^^^^^^^^^^^^^^^^^^^^^^^^
  File "/home/linzhan/anaconda3/lib/python3.12/site-packages/django/contrib/auth/decorators.py", line 60, in _view_wrapper
    return view_func(request, *args, **kwargs)
           ^^^^^^^^^^^^^^^^^^^^^^^^^^^^^^^^^^^
  File "/mnt/d/cmu/capstone_1/base/views.py", line 197, in admin_dashboard
    return render(request, "admin_dashboard.html", {"officers": officers, "logs": logs})
           ^^^^^^^^^^^^^^^^^^^^^^^^^^^^^^^^^^^^^^^^^^^^^^^^^^^^^^^^^^^^^^^^^^^^^^^^^^^^^
  File "/home/linzhan/anaconda3/lib/python3.12/site-packages/django/shortcuts.py", line 25, in render
    content = loader.render_to_string(template_name, context, request, using=using)
              ^^^^^^^^^^^^^^^^^^^^^^^^^^^^^^^^^^^^^^^^^^^^^^^^^^^^^^^^^^^^^^^^^^^^^
  File "/home/linzhan/anaconda3/lib/python3.12/site-packages/django/template/loader.py", line 61, in render_to_string
    template = get_template(template_name, using=using)
               ^^^^^^^^^^^^^^^^^^^^^^^^^^^^^^^^^^^^^^^^
  File "/home/linzhan/anaconda3/lib/python3.12/site-packages/django/template/loader.py", line 15, in get_template
    return engine.get_template(template_name)
           ^^^^^^^^^^^^^^^^^^^^^^^^^^^^^^^^^^
  File "/home/linzhan/anaconda3/lib/python3.12/site-packages/django/template/backends/django.py", line 79, in get_template
    return Template(self.engine.get_template(template_name), self)
                    ^^^^^^^^^^^^^^^^^^^^^^^^^^^^^^^^^^^^^^^
  File "/home/linzhan/anaconda3/lib/python3.12/site-packages/django/template/engine.py", line 177, in get_template
    template, origin = self.find_template(template_name)
                       ^^^^^^^^^^^^^^^^^^^^^^^^^^^^^^^^^
  File "/home/linzhan/anaconda3/lib/python3.12/site-packages/django/template/engine.py", line 159, in find_template
    template = loader.get_template(name, skip=skip)
               ^^^^^^^^^^^^^^^^^^^^^^^^^^^^^^^^^^^^
  File "/home/linzhan/anaconda3/lib/python3.12/site-packages/django/template/loaders/cached.py", line 57, in get_template
    template = super().get_template(template_name, skip)
               ^^^^^^^^^^^^^^^^^^^^^^^^^^^^^^^^^^^^^^^^^
  File "/home/linzhan/anaconda3/lib/python3.12/site-packages/django/template/loaders/base.py", line 28, in get_template
    return Template(
           ^^^^^^^^^
  File "/home/linzhan/anaconda3/lib/python3.12/site-packages/django/template/base.py", line 154, in __init__
    self.nodelist = self.compile_nodelist()
                    ^^^^^^^^^^^^^^^^^^^^^^^
  File "/home/linzhan/anaconda3/lib/python3.12/site-packages/django/template/base.py", line 196, in compile_nodelist
    nodelist = parser.parse()
               ^^^^^^^^^^^^^^
  File "/home/linzhan/anaconda3/lib/python3.12/site-packages/django/template/base.py", line 512, in parse
    self.invalid_block_tag(token, command, parse_until)
  File "/home/linzhan/anaconda3/lib/python3.12/site-packages/django/template/base.py", line 573, in invalid_block_tag
    raise self.error(
django.template.exceptions.TemplateSyntaxError: Invalid block tag on line 51: 'endblock'. Did you forget to register or load this tag?
INFO:django.utils.autoreload:/mnt/d/cmu/capstone_1/base/models.py changed, reloading.
INFO:django.utils.autoreload:/mnt/d/cmu/capstone_1/base/views.py changed, reloading.
INFO:django.utils.autoreload:/mnt/d/cmu/capstone_1/base/views.py changed, reloading.
INFO:django.utils.autoreload:/mnt/d/cmu/capstone_1/base/views.py changed, reloading.
INFO:django.utils.autoreload:/mnt/d/cmu/capstone_1/base/views.py changed, reloading.
ERROR:django.request:Internal Server Error: /update-candidate/1/
Traceback (most recent call last):
  File "/home/linzhan/anaconda3/lib/python3.12/site-packages/django/core/handlers/exception.py", line 55, in inner
    response = get_response(request)
               ^^^^^^^^^^^^^^^^^^^^^
  File "/home/linzhan/anaconda3/lib/python3.12/site-packages/django/core/handlers/base.py", line 197, in _get_response
    response = wrapped_callback(request, *callback_args, **callback_kwargs)
               ^^^^^^^^^^^^^^^^^^^^^^^^^^^^^^^^^^^^^^^^^^^^^^^^^^^^^^^^^^^^
  File "/home/linzhan/anaconda3/lib/python3.12/site-packages/django/contrib/auth/decorators.py", line 60, in _view_wrapper
    return view_func(request, *args, **kwargs)
           ^^^^^^^^^^^^^^^^^^^^^^^^^^^^^^^^^^^
  File "/home/linzhan/anaconda3/lib/python3.12/site-packages/django/contrib/auth/decorators.py", line 60, in _view_wrapper
    return view_func(request, *args, **kwargs)
           ^^^^^^^^^^^^^^^^^^^^^^^^^^^^^^^^^^^
TypeError: update_candidate_status() missing 1 required positional argument: 'new_status'
INFO:django.utils.autoreload:/mnt/d/cmu/capstone_1/base/urls.py changed, reloading.
WARNING:django.request:Not Found: /update-candidate/1/
WARNING:django.request:Not Found: /update-candidate/2/
INFO:django.utils.autoreload:/mnt/d/cmu/capstone_1/base/urls.py changed, reloading.
WARNING:django.request:Not Found: /update-candidate/2/
WARNING:django.request:Not Found: /update-candidate/2/
ERROR:django.request:Internal Server Error: /officer_dashboard/
Traceback (most recent call last):
  File "/home/linzhan/anaconda3/lib/python3.12/site-packages/django/core/handlers/exception.py", line 55, in inner
    response = get_response(request)
               ^^^^^^^^^^^^^^^^^^^^^
  File "/home/linzhan/anaconda3/lib/python3.12/site-packages/django/core/handlers/base.py", line 197, in _get_response
    response = wrapped_callback(request, *callback_args, **callback_kwargs)
               ^^^^^^^^^^^^^^^^^^^^^^^^^^^^^^^^^^^^^^^^^^^^^^^^^^^^^^^^^^^^
  File "/home/linzhan/anaconda3/lib/python3.12/site-packages/django/contrib/auth/decorators.py", line 60, in _view_wrapper
    return view_func(request, *args, **kwargs)
           ^^^^^^^^^^^^^^^^^^^^^^^^^^^^^^^^^^^
  File "/home/linzhan/anaconda3/lib/python3.12/site-packages/django/contrib/auth/decorators.py", line 60, in _view_wrapper
    return view_func(request, *args, **kwargs)
           ^^^^^^^^^^^^^^^^^^^^^^^^^^^^^^^^^^^
  File "/mnt/d/cmu/capstone_1/base/views.py", line 97, in officer_dashboard
    return render(request, "officer_dashboard.html", {"candidates": candidates, "events": events})
           ^^^^^^^^^^^^^^^^^^^^^^^^^^^^^^^^^^^^^^^^^^^^^^^^^^^^^^^^^^^^^^^^^^^^^^^^^^^^^^^^^^^^^^^
  File "/home/linzhan/anaconda3/lib/python3.12/site-packages/django/shortcuts.py", line 25, in render
    content = loader.render_to_string(template_name, context, request, using=using)
              ^^^^^^^^^^^^^^^^^^^^^^^^^^^^^^^^^^^^^^^^^^^^^^^^^^^^^^^^^^^^^^^^^^^^^
  File "/home/linzhan/anaconda3/lib/python3.12/site-packages/django/template/loader.py", line 62, in render_to_string
    return template.render(context, request)
           ^^^^^^^^^^^^^^^^^^^^^^^^^^^^^^^^^
  File "/home/linzhan/anaconda3/lib/python3.12/site-packages/django/template/backends/django.py", line 107, in render
    return self.template.render(context)
           ^^^^^^^^^^^^^^^^^^^^^^^^^^^^^
  File "/home/linzhan/anaconda3/lib/python3.12/site-packages/django/template/base.py", line 171, in render
    return self._render(context)
           ^^^^^^^^^^^^^^^^^^^^^
  File "/home/linzhan/anaconda3/lib/python3.12/site-packages/django/template/base.py", line 163, in _render
    return self.nodelist.render(context)
           ^^^^^^^^^^^^^^^^^^^^^^^^^^^^^
  File "/home/linzhan/anaconda3/lib/python3.12/site-packages/django/template/base.py", line 1008, in render
    return SafeString("".join([node.render_annotated(context) for node in self]))
                               ^^^^^^^^^^^^^^^^^^^^^^^^^^^^^^
  File "/home/linzhan/anaconda3/lib/python3.12/site-packages/django/template/base.py", line 969, in render_annotated
    return self.render(context)
           ^^^^^^^^^^^^^^^^^^^^
  File "/home/linzhan/anaconda3/lib/python3.12/site-packages/django/template/defaulttags.py", line 243, in render
    nodelist.append(node.render_annotated(context))
                    ^^^^^^^^^^^^^^^^^^^^^^^^^^^^^^
  File "/home/linzhan/anaconda3/lib/python3.12/site-packages/django/template/base.py", line 969, in render_annotated
    return self.render(context)
           ^^^^^^^^^^^^^^^^^^^^
  File "/home/linzhan/anaconda3/lib/python3.12/site-packages/django/template/defaulttags.py", line 480, in render
    url = reverse(view_name, args=args, kwargs=kwargs, current_app=current_app)
          ^^^^^^^^^^^^^^^^^^^^^^^^^^^^^^^^^^^^^^^^^^^^^^^^^^^^^^^^^^^^^^^^^^^^^
  File "/home/linzhan/anaconda3/lib/python3.12/site-packages/django/urls/base.py", line 88, in reverse
    return resolver._reverse_with_prefix(view, prefix, *args, **kwargs)
           ^^^^^^^^^^^^^^^^^^^^^^^^^^^^^^^^^^^^^^^^^^^^^^^^^^^^^^^^^^^^
  File "/home/linzhan/anaconda3/lib/python3.12/site-packages/django/urls/resolvers.py", line 831, in _reverse_with_prefix
    raise NoReverseMatch(msg)
django.urls.exceptions.NoReverseMatch: Reverse for 'update_candidate_status' with arguments '(1,)' not found. 1 pattern(s) tried: ['update\\-candidate/(?P<candidate_id>[0-9]+)/(?P<new_status>[^/]+)/\\Z']
INFO:django.utils.autoreload:/mnt/d/cmu/capstone_1/base/urls.py changed, reloading.
ERROR:django.request:Internal Server Error: /admin-dashboard/add-officer/
Traceback (most recent call last):
  File "/home/linzhan/anaconda3/lib/python3.12/site-packages/django/core/handlers/exception.py", line 55, in inner
    response = get_response(request)
               ^^^^^^^^^^^^^^^^^^^^^
  File "/home/linzhan/anaconda3/lib/python3.12/site-packages/django/core/handlers/base.py", line 197, in _get_response
    response = wrapped_callback(request, *callback_args, **callback_kwargs)
               ^^^^^^^^^^^^^^^^^^^^^^^^^^^^^^^^^^^^^^^^^^^^^^^^^^^^^^^^^^^^
  File "/home/linzhan/anaconda3/lib/python3.12/site-packages/django/contrib/auth/decorators.py", line 60, in _view_wrapper
    return view_func(request, *args, **kwargs)
           ^^^^^^^^^^^^^^^^^^^^^^^^^^^^^^^^^^^
  File "/home/linzhan/anaconda3/lib/python3.12/site-packages/django/contrib/auth/decorators.py", line 60, in _view_wrapper
    return view_func(request, *args, **kwargs)
           ^^^^^^^^^^^^^^^^^^^^^^^^^^^^^^^^^^^
  File "/mnt/d/cmu/capstone_1/base/views.py", line 217, in add_officer
    new_officer.set_password(form.cleaned_data["password"])
                             ~~~~~~~~~~~~~~~~~^^^^^^^^^^^^
KeyError: 'password'
INFO:django.utils.autoreload:/mnt/d/cmu/capstone_1/base/views.py changed, reloading.
INFO:django.utils.autoreload:/mnt/d/cmu/capstone_1/webapps/settings.py changed, reloading.
WARNING:django.request:Not Found: /favicon.ico
INFO:django.utils.autoreload:/mnt/d/cmu/capstone_1/base/views.py changed, reloading.
INFO:django.utils.autoreload:/mnt/d/cmu/capstone_1/base/models.py changed, reloading.
INFO:django.utils.autoreload:/mnt/d/cmu/capstone_1/base/views.py changed, reloading.
INFO:django.utils.autoreload:/mnt/d/cmu/capstone_1/base/views.py changed, reloading.
INFO:django.utils.autoreload:/mnt/d/cmu/capstone_1/base/views.py changed, reloading.
INFO:django.utils.autoreload:/mnt/d/cmu/capstone_1/base/views.py changed, reloading.
INFO:django.utils.autoreload:/mnt/d/cmu/capstone_1/base/views.py changed, reloading.
INFO:django.utils.autoreload:/mnt/d/cmu/capstone_1/base/views.py changed, reloading.
INFO:django.utils.autoreload:/mnt/d/cmu/capstone_1/base/views.py changed, reloading.
INFO:django.utils.autoreload:/mnt/d/cmu/capstone_1/base/views.py changed, reloading.
INFO:django.utils.autoreload:/mnt/d/cmu/capstone_1/base/views.py changed, reloading.
INFO:django.utils.autoreload:/mnt/d/cmu/capstone_1/base/views.py changed, reloading.
INFO:django.utils.autoreload:/mnt/d/cmu/capstone_1/base/models.py changed, reloading.
INFO:django.utils.autoreload:/mnt/d/cmu/capstone_1/base/views.py changed, reloading.
INFO:django.utils.autoreload:/mnt/d/cmu/capstone_1/base/views.py changed, reloading.
INFO:django.utils.autoreload:/mnt/d/cmu/capstone_1/base/views.py changed, reloading.
INFO:django.utils.autoreload:/mnt/d/cmu/capstone_1/base/views.py changed, reloading.
INFO:django.utils.autoreload:/mnt/d/cmu/capstone_1/base/views.py changed, reloading.
INFO:django.utils.autoreload:/mnt/d/cmu/capstone_1/base/views.py changed, reloading.
INFO:django.utils.autoreload:/mnt/d/cmu/capstone_1/base/views.py changed, reloading.
INFO:django.utils.autoreload:/mnt/d/cmu/capstone_1/base/views.py changed, reloading.
INFO:django.utils.autoreload:/mnt/d/cmu/capstone_1/base/views.py changed, reloading.
INFO:django.utils.autoreload:/mnt/d/cmu/capstone_1/base/views.py changed, reloading.
INFO:django.utils.autoreload:/mnt/d/cmu/capstone_1/base/views.py changed, reloading.
INFO:django.utils.autoreload:/mnt/d/cmu/capstone_1/base/views.py changed, reloading.
ERROR:django.request:Internal Server Error: /officer_dashboard/
Traceback (most recent call last):
  File "/home/linzhan/anaconda3/lib/python3.12/site-packages/django/core/handlers/exception.py", line 55, in inner
    response = get_response(request)
               ^^^^^^^^^^^^^^^^^^^^^
  File "/home/linzhan/anaconda3/lib/python3.12/site-packages/django/core/handlers/base.py", line 197, in _get_response
    response = wrapped_callback(request, *callback_args, **callback_kwargs)
               ^^^^^^^^^^^^^^^^^^^^^^^^^^^^^^^^^^^^^^^^^^^^^^^^^^^^^^^^^^^^
  File "/home/linzhan/anaconda3/lib/python3.12/site-packages/django/contrib/auth/decorators.py", line 60, in _view_wrapper
    return view_func(request, *args, **kwargs)
           ^^^^^^^^^^^^^^^^^^^^^^^^^^^^^^^^^^^
  File "/home/linzhan/anaconda3/lib/python3.12/site-packages/django/contrib/auth/decorators.py", line 60, in _view_wrapper
    return view_func(request, *args, **kwargs)
           ^^^^^^^^^^^^^^^^^^^^^^^^^^^^^^^^^^^
  File "/mnt/d/cmu/capstone_1/base/views.py", line 164, in officer_dashboard
    return render(request, "officer_dashboard.html", {
           ^^^^^^^^^^^^^^^^^^^^^^^^^^^^^^^^^^^^^^^^^^^
  File "/home/linzhan/anaconda3/lib/python3.12/site-packages/django/shortcuts.py", line 25, in render
    content = loader.render_to_string(template_name, context, request, using=using)
              ^^^^^^^^^^^^^^^^^^^^^^^^^^^^^^^^^^^^^^^^^^^^^^^^^^^^^^^^^^^^^^^^^^^^^
  File "/home/linzhan/anaconda3/lib/python3.12/site-packages/django/template/loader.py", line 62, in render_to_string
    return template.render(context, request)
           ^^^^^^^^^^^^^^^^^^^^^^^^^^^^^^^^^
  File "/home/linzhan/anaconda3/lib/python3.12/site-packages/django/template/backends/django.py", line 107, in render
    return self.template.render(context)
           ^^^^^^^^^^^^^^^^^^^^^^^^^^^^^
  File "/home/linzhan/anaconda3/lib/python3.12/site-packages/django/template/base.py", line 171, in render
    return self._render(context)
           ^^^^^^^^^^^^^^^^^^^^^
  File "/home/linzhan/anaconda3/lib/python3.12/site-packages/django/template/base.py", line 163, in _render
    return self.nodelist.render(context)
           ^^^^^^^^^^^^^^^^^^^^^^^^^^^^^
  File "/home/linzhan/anaconda3/lib/python3.12/site-packages/django/template/base.py", line 1008, in render
    return SafeString("".join([node.render_annotated(context) for node in self]))
                               ^^^^^^^^^^^^^^^^^^^^^^^^^^^^^^
  File "/home/linzhan/anaconda3/lib/python3.12/site-packages/django/template/base.py", line 969, in render_annotated
    return self.render(context)
           ^^^^^^^^^^^^^^^^^^^^
  File "/home/linzhan/anaconda3/lib/python3.12/site-packages/django/template/defaulttags.py", line 480, in render
    url = reverse(view_name, args=args, kwargs=kwargs, current_app=current_app)
          ^^^^^^^^^^^^^^^^^^^^^^^^^^^^^^^^^^^^^^^^^^^^^^^^^^^^^^^^^^^^^^^^^^^^^
  File "/home/linzhan/anaconda3/lib/python3.12/site-packages/django/urls/base.py", line 88, in reverse
    return resolver._reverse_with_prefix(view, prefix, *args, **kwargs)
           ^^^^^^^^^^^^^^^^^^^^^^^^^^^^^^^^^^^^^^^^^^^^^^^^^^^^^^^^^^^^
  File "/home/linzhan/anaconda3/lib/python3.12/site-packages/django/urls/resolvers.py", line 831, in _reverse_with_prefix
    raise NoReverseMatch(msg)
django.urls.exceptions.NoReverseMatch: Reverse for 'add_candidate' not found. 'add_candidate' is not a valid view function or pattern name.
INFO:django.utils.autoreload:/mnt/d/cmu/capstone_1/base/urls.py changed, reloading.
INFO:django.utils.autoreload:/mnt/d/cmu/capstone_1/base/urls.py changed, reloading.
WARNING:django.request:Not Found: /accounts/login/
WARNING:django.request:Not Found: /accounts/login/
WARNING:django.request:Not Found: /accounts/login/
